I was getting errors stopping application. That is a confirmed bug.
https://github.com/python/asyncio/issues/258
https://github.com/aio-libs/aiohttp/issues/441



Fix Pull Request:
https://github.com/python/cpython/commit/319c0345cdd8fddb49d235462e71883f1dd51b99